Workbook

Sheet Guide
A1: Hospital Disputes Tracker v1.0 (F3) - 28 October 2026
A2: Prepared by KPMG for the CNHI audit project. Blank template.
A4: Purpose | B4: One place to register every hospital objection, record KPMG's position and the actions taken, and feed the dashboard (Hospital disputes page and EX-07, EX-08). Effort hours are visible to CNHI (Decision D-15).
A5: How it fits | B5: Batches: one row per objection file a hospital sends (dates entered once). Disputes: one row per disputed claim or approval, linked to its batch. Actions: every action and its hours, linked to a dispute or a batch. Summary: totals, calculated.
A6: 1. New batch | B6: Add a row in Batches: hospital, TPA, pathway, claims period, file name and the date it was received.
A7: 2. Register disputes | B7: Add one row per disputed claim in Disputes with the batch ID, references, rejection codes, the TPA or CNHI position and the hospital's argument in one line each, the claimed amount and the approved amount from NPHIES. The amount disputed is calculated (claimed minus approved).
A8: 3. Review | B8: Record the KPMG position (Not accepted, Partially accepted, Accepted, Withdrawn by hospital), the recommended action, the FWA indicator and the comment. For partial acceptance enter the value to pay; the value maintained is calculated.
A9: 4. Dates | B9: The received date and the KPMG opinion date come from the batch. Enter a date on the dispute row only when it differs. Yellow cells are missing dates or amounts that the dashboard needs.
A10: 5. Actions and hours | B10: Log each action with its hours in Actions, from 1 October 2026. Hours reconstructed for past days: set 'Estimated?' to Yes.
A11: 6. CNHI decision | B11: When CNHI decides, enter the sent date, the decision and its date, and set the status to Closed.
A12: Dashboard mapping | B12: Closed in a month = KPMG opinion issued in that month. Outcome: Not accepted = rejection maintained; Partially accepted = partially maintained; Accepted = reversed. Value disputed = claimed minus approved.
A13: Data protection | B13: No patient names, national IDs or file numbers. The dashboard hashes the references and drops all free-text columns (comments, arguments, notes) at upload.
A15: دليل مختصر
B16: سجل كل ملف اعتراض يرد من المستشفى في ورقة الدفعات، وأدخل تاريخ الاستلام مرة واحدة.
B17: سجل كل مطالبة معترض عليها في ورقة الاعتراضات مع رقم الدفعة والمراجع ورموز الرفض والمبلغ المطالب به والمعتمد.
B18: سجل موقف كي بي إم جي والإجراء الموصى به ومؤشر الاحتيال والهدر، والقيمة المستحقة الدفع عند القبول الجزئي.
B19: سجل كل إجراء وساعات العمل عليه في ورقة الإجراءات بدءا من 1 أكتوبر 2026.
B20: لا تدخل اسم المريض أو رقم الهوية أو الرقم الطبي.

Sheet Summary
A1: Hospital disputes - summary
A2: Calculated from the Disputes and Actions sheets. Feeds the dashboard page 'Hospital disputes' (EX-07, EX-08, HD-01 to HD-07).
A4: Headline | B4: Value
A5: Disputes registered | B5: =COUNTA(Disputes!$A$5:$A$1004) -> 0
A6: KPMG opinions issued | B6: =COUNTIF(Disputes!$AI$5:$AI$1004,"?*") -> 0
A7: Pending KPMG review | B7: =COUNTIF(Disputes!$X$5:$X$1004,"Pending") -> 0
A8: Rejection maintained in full (Not accepted) | B8: =COUNTIF(Disputes!$X$5:$X$1004,"Not accepted") -> 0
A9: Position maintained rate (full) | B9: =IF(B6=0,"-",B8/B6) -> -
A10: Claimed value of disputed claims (SAR) | B10: =SUM(Disputes!$P$5:$P$1004) -> 0
A11: Amount disputed (SAR) - where approved amount entered | B11: =SUM(Disputes!$R$5:$R$1004) -> 0
A12: Value maintained (SAR) | B12: =SUM(Disputes!$AA$5:$AA$1004) -> 0
A13: Disputes still missing the approved amount | B13: =COUNTIFS(Disputes!$A$5:$A$1004,"?*",Disputes!$Q$5:$Q$1004,"",Disputes!$X$5:$X$1004,"<>Pending") -> 0
A14: Disputes with an FWA indicator | B14: =COUNTA(Disputes!$AB$5:$AB$1004)-COUNTIF(Disputes!$AB$5:$AB$1004,"None") -> 0
A15: Hours logged | B15: =SUM(Actions!$F$5:$F$1004)-SUMIF(Actions!$C$5:$C$1004,"EXAMPLE",Actions!$F$5:$F$1004) -> 0
A16: Median days from receipt to opinion | B16: =IFERROR(MEDIAN(Disputes!$AK$5:$AK$1004),"-") -> -
A19: By hospital | B19: Disputes | C19: Not accepted | D19: Partially accepted | E19: Accepted | F19: Pending | G19: Claimed (SAR) | H19: Value maintained (SAR) | I19: FWA flags | J19: Hours
A20: Al-Ahly Hospital | B20: =COUNTIFS(Disputes!$C$5:$C$1004,$A20) -> 0 | C20: =COUNTIFS(Disputes!$C$5:$C$1004,$A20,Disputes!$X$5:$X$1004,"Not accepted") -> 0 | D20: =COUNTIFS(Disputes!$C$5:$C$1004,$A20,Disputes!$X$5:$X$1004,"Partially accepted") -> 0 | E20: =COUNTIFS(Disputes!$C$5:$C$1004,$A20,Disputes!$X$5:$X$1004,"Accepted") -> 0 | F20: =COUNTIFS(Disputes!$C$5:$C$1004,$A20,Disputes!$X$5:$X$1004,"Pending") -> 0 | G20: =SUMIFS(Disputes!$P$5:$P$1004,Disputes!$C$5:$C$1004,$A20) -> 0 | H20: =SUMIFS(Disputes!$AA$5:$AA$1004,Disputes!$C$5:$C$1004,$A20) -> 0 | I20: =COUNTIFS(Disputes!$C$5:$C$1004,$A20,Disputes!$AB$5:$AB$1004,"<>None",Disputes!$AB$5:$AB$1004,"<>") -> 0 | J20: =SUMIF(Actions!$I$5:$I$1004,$A20,Actions!$F$5:$F$1004) -> 0
A21: Al Khafji Ahli Hospital | B21: =COUNTIFS(Disputes!$C$5:$C$1004,$A21) -> 0 | C21: =COUNTIFS(Disputes!$C$5:$C$1004,$A21,Disputes!$X$5:$X$1004,"Not accepted") -> 0 | D21: =COUNTIFS(Disputes!$C$5:$C$1004,$A21,Disputes!$X$5:$X$1004,"Partially accepted") -> 0 | E21: =COUNTIFS(Disputes!$C$5:$C$1004,$A21,Disputes!$X$5:$X$1004,"Accepted") -> 0 | F21: =COUNTIFS(Disputes!$C$5:$C$1004,$A21,Disputes!$X$5:$X$1004,"Pending") -> 0 | G21: =SUMIFS(Disputes!$P$5:$P$1004,Disputes!$C$5:$C$1004,$A21) -> 0 | H21: =SUMIFS(Disputes!$AA$5:$AA$1004,Disputes!$C$5:$C$1004,$A21) -> 0 | I21: =COUNTIFS(Disputes!$C$5:$C$1004,$A21,Disputes!$AB$5:$AB$1004,"<>None",Disputes!$AB$5:$AB$1004,"<>") -> 0 | J21: =SUMIF(Actions!$I$5:$I$1004,$A21,Actions!$F$5:$F$1004) -> 0
A22: Dr. Fares Al-Haddaj Hospital | B22: =COUNTIFS(Disputes!$C$5:$C$1004,$A22) -> 0 | C22: =COUNTIFS(Disputes!$C$5:$C$1004,$A22,Disputes!$X$5:$X$1004,"Not accepted") -> 0 | D22: =COUNTIFS(Disputes!$C$5:$C$1004,$A22,Disputes!$X$5:$X$1004,"Partially accepted") -> 0 | E22: =COUNTIFS(Disputes!$C$5:$C$1004,$A22,Disputes!$X$5:$X$1004,"Accepted") -> 0 | F22: =COUNTIFS(Disputes!$C$5:$C$1004,$A22,Disputes!$X$5:$X$1004,"Pending") -> 0 | G22: =SUMIFS(Disputes!$P$5:$P$1004,Disputes!$C$5:$C$1004,$A22) -> 0 | H22: =SUMIFS(Disputes!$AA$5:$AA$1004,Disputes!$C$5:$C$1004,$A22) -> 0 | I22: =COUNTIFS(Disputes!$C$5:$C$1004,$A22,Disputes!$AB$5:$AB$1004,"<>None",Disputes!$AB$5:$AB$1004,"<>") -> 0 | J22: =SUMIF(Actions!$I$5:$I$1004,$A22,Actions!$F$5:$F$1004) -> 0
A23: Almodawat Hospital | B23: =COUNTIFS(Disputes!$C$5:$C$1004,$A23) -> 0 | C23: =COUNTIFS(Disputes!$C$5:$C$1004,$A23,Disputes!$X$5:$X$1004,"Not accepted") -> 0 | D23: =COUNTIFS(Disputes!$C$5:$C$1004,$A23,Disputes!$X$5:$X$1004,"Partially accepted") -> 0 | E23: =COUNTIFS(Disputes!$C$5:$C$1004,$A23,Disputes!$X$5:$X$1004,"Accepted") -> 0 | F23: =COUNTIFS(Disputes!$C$5:$C$1004,$A23,Disputes!$X$5:$X$1004,"Pending") -> 0 | G23: =SUMIFS(Disputes!$P$5:$P$1004,Disputes!$C$5:$C$1004,$A23) -> 0 | H23: =SUMIFS(Disputes!$AA$5:$AA$1004,Disputes!$C$5:$C$1004,$A23) -> 0 | I23: =COUNTIFS(Disputes!$C$5:$C$1004,$A23,Disputes!$AB$5:$AB$1004,"<>None",Disputes!$AB$5:$AB$1004,"<>") -> 0 | J23: =SUMIF(Actions!$I$5:$I$1004,$A23,Actions!$F$5:$F$1004) -> 0
A24: Total | B24: =SUM(B20:B23) -> 0 | C24: =SUM(C20:C23) -> 0 | D24: =SUM(D20:D23) -> 0 | E24: =SUM(E20:E23) -> 0 | F24: =SUM(F20:F23) -> 0 | G24: =SUM(G20:G23) -> 0 | H24: =SUM(H20:H23) -> 0 | I24: =SUM(I20:I23) -> 0 | J24: =SUM(J20:J23) -> 0
A27: By dispute theme | B27: Disputes | C27: Not accepted | D27: Partially accepted | E27: Accepted | F27: Share
A28: Level of care (ICU/PICU) | B28: =COUNTIFS(Disputes!$O$5:$O$1004,$A28) -> 0 | C28: =COUNTIFS(Disputes!$O$5:$O$1004,$A28,Disputes!$X$5:$X$1004,"Not accepted") -> 0 | D28: =COUNTIFS(Disputes!$O$5:$O$1004,$A28,Disputes!$X$5:$X$1004,"Partially accepted") -> 0 | E28: =COUNTIFS(Disputes!$O$5:$O$1004,$A28,Disputes!$X$5:$X$1004,"Accepted") -> 0 | F28: =IF($B$5=0,0,B28/$B$5) -> 0
A29: Length of stay | B29: =COUNTIFS(Disputes!$O$5:$O$1004,$A29) -> 0 | C29: =COUNTIFS(Disputes!$O$5:$O$1004,$A29,Disputes!$X$5:$X$1004,"Not accepted") -> 0 | D29: =COUNTIFS(Disputes!$O$5:$O$1004,$A29,Disputes!$X$5:$X$1004,"Partially accepted") -> 0 | E29: =COUNTIFS(Disputes!$O$5:$O$1004,$A29,Disputes!$X$5:$X$1004,"Accepted") -> 0 | F29: =IF($B$5=0,0,B29/$B$5) -> 0
A30: Pre-authorization missing or expired | B30: =COUNTIFS(Disputes!$O$5:$O$1004,$A30) -> 0 | C30: =COUNTIFS(Disputes!$O$5:$O$1004,$A30,Disputes!$X$5:$X$1004,"Not accepted") -> 0 | D30: =COUNTIFS(Disputes!$O$5:$O$1004,$A30,Disputes!$X$5:$X$1004,"Partially accepted") -> 0 | E30: =COUNTIFS(Disputes!$O$5:$O$1004,$A30,Disputes!$X$5:$X$1004,"Accepted") -> 0 | F30: =IF($B$5=0,0,B30/$B$5) -> 0
A31: Coding or billing | B31: =COUNTIFS(Disputes!$O$5:$O$1004,$A31) -> 0 | C31: =COUNTIFS(Disputes!$O$5:$O$1004,$A31,Disputes!$X$5:$X$1004,"Not accepted") -> 0 | D31: =COUNTIFS(Disputes!$O$5:$O$1004,$A31,Disputes!$X$5:$X$1004,"Partially accepted") -> 0 | E31: =COUNTIFS(Disputes!$O$5:$O$1004,$A31,Disputes!$X$5:$X$1004,"Accepted") -> 0 | F31: =IF($B$5=0,0,B31/$B$5) -> 0
A32: Long-term care / ventilation | B32: =COUNTIFS(Disputes!$O$5:$O$1004,$A32) -> 0 | C32: =COUNTIFS(Disputes!$O$5:$O$1004,$A32,Disputes!$X$5:$X$1004,"Not accepted") -> 0 | D32: =COUNTIFS(Disputes!$O$5:$O$1004,$A32,Disputes!$X$5:$X$1004,"Partially accepted") -> 0 | E32: =COUNTIFS(Disputes!$O$5:$O$1004,$A32,Disputes!$X$5:$X$1004,"Accepted") -> 0 | F32: =IF($B$5=0,0,B32/$B$5) -> 0
A33: Medical necessity | B33: =COUNTIFS(Disputes!$O$5:$O$1004,$A33) -> 0 | C33: =COUNTIFS(Disputes!$O$5:$O$1004,$A33,Disputes!$X$5:$X$1004,"Not accepted") -> 0 | D33: =COUNTIFS(Disputes!$O$5:$O$1004,$A33,Disputes!$X$5:$X$1004,"Partially accepted") -> 0 | E33: =COUNTIFS(Disputes!$O$5:$O$1004,$A33,Disputes!$X$5:$X$1004,"Accepted") -> 0 | F33: =IF($B$5=0,0,B33/$B$5) -> 0
A34: Pricing or tariff | B34: =COUNTIFS(Disputes!$O$5:$O$1004,$A34) -> 0 | C34: =COUNTIFS(Disputes!$O$5:$O$1004,$A34,Disputes!$X$5:$X$1004,"Not accepted") -> 0 | D34: =COUNTIFS(Disputes!$O$5:$O$1004,$A34,Disputes!$X$5:$X$1004,"Partially accepted") -> 0 | E34: =COUNTIFS(Disputes!$O$5:$O$1004,$A34,Disputes!$X$5:$X$1004,"Accepted") -> 0 | F34: =IF($B$5=0,0,B34/$B$5) -> 0
A35: Documentation | B35: =COUNTIFS(Disputes!$O$5:$O$1004,$A35) -> 0 | C35: =COUNTIFS(Disputes!$O$5:$O$1004,$A35,Disputes!$X$5:$X$1004,"Not accepted") -> 0 | D35: =COUNTIFS(Disputes!$O$5:$O$1004,$A35,Disputes!$X$5:$X$1004,"Partially accepted") -> 0 | E35: =COUNTIFS(Disputes!$O$5:$O$1004,$A35,Disputes!$X$5:$X$1004,"Accepted") -> 0 | F35: =IF($B$5=0,0,B35/$B$5) -> 0
A36: Other | B36: =COUNTIFS(Disputes!$O$5:$O$1004,$A36) -> 0 | C36: =COUNTIFS(Disputes!$O$5:$O$1004,$A36,Disputes!$X$5:$X$1004,"Not accepted") -> 0 | D36: =COUNTIFS(Disputes!$O$5:$O$1004,$A36,Disputes!$X$5:$X$1004,"Partially accepted") -> 0 | E36: =COUNTIFS(Disputes!$O$5:$O$1004,$A36,Disputes!$X$5:$X$1004,"Accepted") -> 0 | F36: =IF($B$5=0,0,B36/$B$5) -> 0
A39: By FWA indicator | B39: Disputes
A40: None | B40: =COUNTIF(Disputes!$AB$5:$AB$1004,$A40) -> 0
A41: Waste (overpayment risk) | B41: =COUNTIF(Disputes!$AB$5:$AB$1004,$A41) -> 0
A42: Potential abuse | B42: =COUNTIF(Disputes!$AB$5:$AB$1004,$A42) -> 0
A43: Suspected abuse | B43: =COUNTIF(Disputes!$AB$5:$AB$1004,$A43) -> 0
A44: Suspected fraud | B44: =COUNTIF(Disputes!$AB$5:$AB$1004,$A44) -> 0
A47: By recommended action | B47: Disputes
A48: Uphold rejection | B48: =COUNTIF(Disputes!$Y$5:$Y$1004,$A48) -> 0
A49: Partial payment | B49: =COUNTIF(Disputes!$Y$5:$Y$1004,$A49) -> 0
...

Sheet Batches
A1: Batches: one row per objection file received from a hospital
A2: Enter the dates once per batch; every dispute in the batch takes them unless its own row overrides them. Yellow = to confirm.
A4: Batch ID | B4: Hospital | C4: TPA | D4: Pathway | E4: Claims period | F4: Source file | G4: Received date | H4: KPMG opinion date | I4: Sent to CNHI date | J4: Disputes | K4: Opinions issued | L4: Notes

Sheet Disputes
A1: Hospital disputes register: one row per disputed claim or approval
A2: Navy headers: you enter or correct. Grey headers: calculated, do not type over. Row 3 gives the Arabic label of each column.
A3: رقم الاعتراض | B3: رقم الدفعة | C3: المستشفى | D3: شركة إدارة المطالبات | E3: المسار | F3: الجولة | G3: رقم GSS | H3: مرجع المطالبة | I3: رقم المطالبة | J3: شهر الفوترة | K3: تاريخ الخدمة | L3: رموز الرفض | M3: موقف الشركة أو المركز | N3: حجة المستشفى | O3: موضوع الاعتراض | P3: المبلغ المطالب به | Q3: المبلغ المعتمد | R3: المبلغ محل الاعتراض | S3: تاريخ الاستلام (إن اختلف) | T3: تاريخ الاستلام | U3: المراجع | V3: تاريخ الرأي (إن اختلف) | W3: تاريخ رأي كي بي إم جي | X3: موقف كي بي إم جي | Y3: الإجراء الموصى به | Z3: القيمة المستحقة الدفع (للقبول الجزئي) | AA3: القيمة المحافظ عليها | AB3: مؤشر الاحتيال والهدر | AC3: ملخص رأي كي بي إم جي | AD3: رأي كي بي إم جي كاملا | AE3: الحالة | AF3: تاريخ الإرسال للمركز | AG3: قرار المركز النهائي | AH3: تاريخ قرار المركز | AI3: النتيجة | AJ3: تاريخ الإغلاق | AK3: أيام حتى الرأي | AL3: الساعات المسجلة | AM3: المصدر والملاحظات
A4: Dispute ID | B4: Batch ID | C4: Hospital | D4: TPA | E4: Pathway | F4: Round | G4: GSS ID | H4: Claim or bundle reference | I4: Claim no. | J4: Billing month | K4: Service or admission date | L4: Rejection code(s) | M4: TPA or CNHI position (summary) | N4: Hospital argument (summary) | O4: Dispute theme | P4: Claimed amount (SAR) | Q4: Approved amount (SAR) | R4: Amount disputed (SAR) | S4: Received date (if different from batch) | T4: Received date | U4: KPMG reviewer | V4: KPMG opinion date (if different from batch) | W4: KPMG opinion date | X4: KPMG position | Y4: Recommended action | Z4: Value to pay (SAR) - partial only | AA4: Value maintained (SAR) | AB4: FWA indicator | AC4: KPMG comment (summary) | AD4: KPMG comment (full) | AE4: Status | AF4: Sent to CNHI date | AG4: CNHI final decision | AH4: CNHI decision date | AI4: Outcome | AJ4: Closure date | AK4: Days to opinion | AL4: Hours logged | AM4: Source and notes
R5: =IF(AND(ISNUMBER(P5),ISNUMBER(Q5)),P5-Q5,"") | T5: =IF(S5<>"",S5,IF(B5="","",IFERROR(IF(INDEX(Batches!$G$5:$G$64,MATCH(B5,Batches!$A$5:$A$64,0))="","",INDEX(Batches!$G$5:$G$64,MATCH(B5,Batches!$A$5:$A$64,0))),""))) | W5: =IF(OR(X5="",X5="Pending"),"",IF(V5<>"",V5,IFERROR(IF(INDEX(Batches!$H$5:$H$64,MATCH(B5,Batches!$A$5:$A$64,0))="","",INDEX(Batches!$H$5:$H$64,MATCH(B5,Batches!$A$5:$A$64,0))),""))) | AA5: =IF(R5="","",IF(X5="Not accepted",R5,IF(OR(X5="Accepted",X5="Withdrawn by hospital"),IF(X5="Accepted",0,R5),IF(ISNUMBER(Z5),R5-Z5,"")))) | AI5: =IF(X5="Not accepted","Maintained",IF(X5="Partially accepted","Partially maintained",IF(X5="Accepted","Reversed",IF(X5="Withdrawn by hospital","Withdrawn by hospital","")))) | AJ5: =IF(AI5="","",W5) | AK5: =IF(AND(ISNUMBER(T5),ISNUMBER(W5)),W5-T5,"") | AL5: =IF(A5="","",SUMIF(Actions!$C$5:$C$1004,A5,Actions!$F$5:$F$1004))
R6: =IF(AND(ISNUMBER(P6),ISNUMBER(Q6)),P6-Q6,"") | T6: =IF(S6<>"",S6,IF(B6="","",IFERROR(IF(INDEX(Batches!$G$5:$G$64,MATCH(B6,Batches!$A$5:$A$64,0))="","",INDEX(Batches!$G$5:$G$64,MATCH(B6,Batches!$A$5:$A$64,0))),""))) | W6: =IF(OR(X6="",X6="Pending"),"",IF(V6<>"",V6,IFERROR(IF(INDEX(Batches!$H$5:$H$64,MATCH(B6,Batches!$A$5:$A$64,0))="","",INDEX(Batches!$H$5:$H$64,MATCH(B6,Batches!$A$5:$A$64,0))),""))) | AA6: =IF(R6="","",IF(X6="Not accepted",R6,IF(OR(X6="Accepted",X6="Withdrawn by hospital"),IF(X6="Accepted",0,R6),IF(ISNUMBER(Z6),R6-Z6,"")))) | AI6: =IF(X6="Not accepted","Maintained",IF(X6="Partially accepted","Partially maintained",IF(X6="Accepted","Reversed",IF(X6="Withdrawn by hospital","Withdrawn by hospital","")))) | AJ6: =IF(AI6="","",W6) | AK6: =IF(AND(ISNUMBER(T6),ISNUMBER(W6)),W6-T6,"") | AL6: =IF(A6="","",SUMIF(Actions!$C$5:$C$1004,A6,Actions!$F$5:$F$1004))
R7: =IF(AND(ISNUMBER(P7),ISNUMBER(Q7)),P7-Q7,"") | T7: =IF(S7<>"",S7,IF(B7="","",IFERROR(IF(INDEX(Batches!$G$5:$G$64,MATCH(B7,Batches!$A$5:$A$64,0))="","",INDEX(Batches!$G$5:$G$64,MATCH(B7,Batches!$A$5:$A$64,0))),""))) | W7: =IF(OR(X7="",X7="Pending"),"",IF(V7<>"",V7,IFERROR(IF(INDEX(Batches!$H$5:$H$64,MATCH(B7,Batches!$A$5:$A$64,0))="","",INDEX(Batches!$H$5:$H$64,MATCH(B7,Batches!$A$5:$A$64,0))),""))) | AA7: =IF(R7="","",IF(X7="Not accepted",R7,IF(OR(X7="Accepted",X7="Withdrawn by hospital"),IF(X7="Accepted",0,R7),IF(ISNUMBER(Z7),R7-Z7,"")))) | AI7: =IF(X7="Not accepted","Maintained",IF(X7="Partially accepted","Partially maintained",IF(X7="Accepted","Reversed",IF(X7="Withdrawn by hospital","Withdrawn by hospital","")))) | AJ7: =IF(AI7="","",W7) | AK7: =IF(AND(ISNUMBER(T7),ISNUMBER(W7)),W7-T7,"") | AL7: =IF(A7="","",SUMIF(Actions!$C$5:$C$1004,A7,Actions!$F$5:$F$1004))
R8: =IF(AND(ISNUMBER(P8),ISNUMBER(Q8)),P8-Q8,"") | T8: =IF(S8<>"",S8,IF(B8="","",IFERROR(IF(INDEX(Batches!$G$5:$G$64,MATCH(B8,Batches!$A$5:$A$64,0))="","",INDEX(Batches!$G$5:$G$64,MATCH(B8,Batches!$A$5:$A$64,0))),""))) | W8: =IF(OR(X8="",X8="Pending"),"",IF(V8<>"",V8,IFERROR(IF(INDEX(Batches!$H$5:$H$64,MATCH(B8,Batches!$A$5:$A$64,0))="","",INDEX(Batches!$H$5:$H$64,MATCH(B8,Batches!$A$5:$A$64,0))),""))) | AA8: =IF(R8="","",IF(X8="Not accepted",R8,IF(OR(X8="Accepted",X8="Withdrawn by hospital"),IF(X8="Accepted",0,R8),IF(ISNUMBER(Z8),R8-Z8,"")))) | AI8: =IF(X8="Not accepted","Maintained",IF(X8="Partially accepted","Partially maintained",IF(X8="Accepted","Reversed",IF(X8="Withdrawn by hospital","Withdrawn by hospital","")))) | AJ8: =IF(AI8="","",W8) | AK8: =IF(AND(ISNUMBER(T8),ISNUMBER(W8)),W8-T8,"") | AL8: =IF(A8="","",SUMIF(Actions!$C$5:$C$1004,A8,Actions!$F$5:$F$1004))
R9: =IF(AND(ISNUMBER(P9),ISNUMBER(Q9)),P9-Q9,"") | T9: =IF(S9<>"",S9,IF(B9="","",IFERROR(IF(INDEX(Batches!$G$5:$G$64,MATCH(B9,Batches!$A$5:$A$64,0))="","",INDEX(Batches!$G$5:$G$64,MATCH(B9,Batches!$A$5:$A$64,0))),""))) | W9: =IF(OR(X9="",X9="Pending"),"",IF(V9<>"",V9,IFERROR(IF(INDEX(Batches!$H$5:$H$64,MATCH(B9,Batches!$A$5:$A$64,0))="","",INDEX(Batches!$H$5:$H$64,MATCH(B9,Batches!$A$5:$A$64,0))),""))) | AA9: =IF(R9="","",IF(X9="Not accepted",R9,IF(OR(X9="Accepted",X9="Withdrawn by hospital"),IF(X9="Accepted",0,R9),IF(ISNUMBER(Z9),R9-Z9,"")))) | AI9: =IF(X9="Not accepted","Maintained",IF(X9="Partially accepted","Partially maintained",IF(X9="Accepted","Reversed",IF(X9="Withdrawn by hospital","Withdrawn by hospital","")))) | AJ9: =IF(AI9="","",W9) | AK9: =IF(AND(ISNUMBER(T9),ISNUMBER(W9)),W9-T9,"") | AL9: =IF(A9="","",SUMIF(Actions!$C$5:$C$1004,A9,Actions!$F$5:$F$1004))
R10: =IF(AND(ISNUMBER(P10),ISNUMBER(Q10)),P10-Q10,"") | T10: =IF(S10<>"",S10,IF(B10="","",IFERROR(IF(INDEX(Batches!$G$5:$G$64,MATCH(B10,Batches!$A$5:$A$64,0))="","",INDEX(Batches!$G$5:$G$64,MATCH(B10,Batches!$A$5:$A$64,0))),""))) | W10: =IF(OR(X10="",X10="Pending"),"",IF(V10<>"",V10,IFERROR(IF(INDEX(Batches!$H$5:$H$64,MATCH(B10,Batches!$A$5:$A$64,0))="","",INDEX(Batches!$H$5:$H$64,MATCH(B10,Batches!$A$5:$A$64,0))),""))) | AA10: =IF(R10="","",IF(X10="Not accepted",R10,IF(OR(X10="Accepted",X10="Withdrawn by hospital"),IF(X10="Accepted",0,R10),IF(ISNUMBER(Z10),R10-Z10,"")))) | AI10: =IF(X10="Not accepted","Maintained",IF(X10="Partially accepted","Partially maintained",IF(X10="Accepted","Reversed",IF(X10="Withdrawn by hospital","Withdrawn by hospital","")))) | AJ10: =IF(AI10="","",W10) | AK10: =IF(AND(ISNUMBER(T10),ISNUMBER(W10)),W10-T10,"") | AL10: =IF(A10="","",SUMIF(Actions!$C$5:$C$1004,A10,Actions!$F$5:$F$1004))
R11: =IF(AND(ISNUMBER(P11),ISNUMBER(Q11)),P11-Q11,"") | T11: =IF(S11<>"",S11,IF(B11="","",IFERROR(IF(INDEX(Batches!$G$5:$G$64,MATCH(B11,Batches!$A$5:$A$64,0))="","",INDEX(Batches!$G$5:$G$64,MATCH(B11,Batches!$A$5:$A$64,0))),""))) | W11: =IF(OR(X11="",X11="Pending"),"",IF(V11<>"",V11,IFERROR(IF(INDEX(Batches!$H$5:$H$64,MATCH(B11,Batches!$A$5:$A$64,0))="","",INDEX(Batches!$H$5:$H$64,MATCH(B11,Batches!$A$5:$A$64,0))),""))) | AA11: =IF(R11="","",IF(X11="Not accepted",R11,IF(OR(X11="Accepted",X11="Withdrawn by hospital"),IF(X11="Accepted",0,R11),IF(ISNUMBER(Z11),R11-Z11,"")))) | AI11: =IF(X11="Not accepted","Maintained",IF(X11="Partially accepted","Partially maintained",IF(X11="Accepted","Reversed",IF(X11="Withdrawn by hospital","Withdrawn by hospital","")))) | AJ11: =IF(AI11="","",W11) | AK11: =IF(AND(ISNUMBER(T11),ISNUMBER(W11)),W11-T11,"") | AL11: =IF(A11="","",SUMIF(Actions!$C$5:$C$1004,A11,Actions!$F$5:$F$1004))
R12: =IF(AND(ISNUMBER(P12),ISNUMBER(Q12)),P12-Q12,"") | T12: =IF(S12<>"",S12,IF(B12="","",IFERROR(IF(INDEX(Batches!$G$5:$G$64,MATCH(B12,Batches!$A$5:$A$64,0))="","",INDEX(Batches!$G$5:$G$64,MATCH(B12,Batches!$A$5:$A$64,0))),""))) | W12: =IF(OR(X12="",X12="Pending"),"",IF(V12<>"",V12,IFERROR(IF(INDEX(Batches!$H$5:$H$64,MATCH(B12,Batches!$A$5:$A$64,0))="","",INDEX(Batches!$H$5:$H$64,MATCH(B12,Batches!$A$5:$A$64,0))),""))) | AA12: =IF(R12="","",IF(X12="Not accepted",R12,IF(OR(X12="Accepted",X12="Withdrawn by hospital"),IF(X12="Accepted",0,R12),IF(ISNUMBER(Z12),R12-Z12,"")))) | AI12: =IF(X12="Not accepted","Maintained",IF(X12="Partially accepted","Partially maintained",IF(X12="Accepted","Reversed",IF(X12="Withdrawn by hospital","Withdrawn by hospital","")))) | AJ12: =IF(AI12="","",W12) | AK12: =IF(AND(ISNUMBER(T12),ISNUMBER(W12)),W12-T12,"") | AL12: =IF(A12="","",SUMIF(Actions!$C$5:$C$1004,A12,Actions!$F$5:$F$1004))
R13: =IF(AND(ISNUMBER(P13),ISNUMBER(Q13)),P13-Q13,"") | T13: =IF(S13<>"",S13,IF(B13="","",IFERROR(IF(INDEX(Batches!$G$5:$G$64,MATCH(B13,Batches!$A$5:$A$64,0))="","",INDEX(Batches!$G$5:$G$64,MATCH(B13,Batches!$A$5:$A$64,0))),""))) | W13: =IF(OR(X13="",X13="Pending"),"",IF(V13<>"",V13,IFERROR(IF(INDEX(Batches!$H$5:$H$64,MATCH(B13,Batches!$A$5:$A$64,0))="","",INDEX(Batches!$H$5:$H$64,MATCH(B13,Batches!$A$5:$A$64,0))),""))) | AA13: =IF(R13="","",IF(X13="Not accepted",R13,IF(OR(X13="Accepted",X13="Withdrawn by hospital"),IF(X13="Accepted",0,R13),IF(ISNUMBER(Z13),R13-Z13,"")))) | AI13: =IF(X13="Not accepted","Maintained",IF(X13="Partially accepted","Partially maintained",IF(X13="Accepted","Reversed",IF(X13="Withdrawn by hospital","Withdrawn by hospital","")))) | AJ13: =IF(AI13="","",W13) | AK13: =IF(AND(ISNUMBER(T13),ISNUMBER(W13)),W13-T13,"") | AL13: =IF(A13="","",SUMIF(Actions!$C$5:$C$1004,A13,Actions!$F$5:$F$1004))
R14: =IF(AND(ISNUMBER(P14),ISNUMBER(Q14)),P14-Q14,"") | T14: =IF(S14<>"",S14,IF(B14="","",IFERROR(IF(INDEX(Batches!$G$5:$G$64,MATCH(B14,Batches!$A$5:$A$64,0))="","",INDEX(Batches!$G$5:$G$64,MATCH(B14,Batches!$A$5:$A$64,0))),""))) | W14: =IF(OR(X14="",X14="Pending"),"",IF(V14<>"",V14,IFERROR(IF(INDEX(Batches!$H$5:$H$64,MATCH(B14,Batches!$A$5:$A$64,0))="","",INDEX(Batches!$H$5:$H$64,MATCH(B14,Batches!$A$5:$A$64,0))),""))) | AA14: =IF(R14="","",IF(X14="Not accepted",R14,IF(OR(X14="Accepted",X14="Withdrawn by hospital"),IF(X14="Accepted",0,R14),IF(ISNUMBER(Z14),R14-Z14,"")))) | AI14: =IF(X14="Not accepted","Maintained",IF(X14="Partially accepted","Partially maintained",IF(X14="Accepted","Reversed",IF(X14="Withdrawn by hospital","Withdrawn by hospital","")))) | AJ14: =IF(AI14="","",W14) | AK14: =IF(AND(ISNUMBER(T14),ISNUMBER(W14)),W14-T14,"") | AL14: =IF(A14="","",SUMIF(Actions!$C$5:$C$1004,A14,Actions!$F$5:$F$1004))
R15: =IF(AND(ISNUMBER(P15),ISNUMBER(Q15)),P15-Q15,"") | T15: =IF(S15<>"",S15,IF(B15="","",IFERROR(IF(INDEX(Batches!$G$5:$G$64,MATCH(B15,Batches!$A$5:$A$64,0))="","",INDEX(Batches!$G$5:$G$64,MATCH(B15,Batches!$A$5:$A$64,0))),""))) | W15: =IF(OR(X15="",X15="Pending"),"",IF(V15<>"",V15,IFERROR(IF(INDEX(Batches!$H$5:$H$64,MATCH(B15,Batches!$A$5:$A$64,0))="","",INDEX(Batches!$H$5:$H$64,MATCH(B15,Batches!$A$5:$A$64,0))),""))) | AA15: =IF(R15="","",IF(X15="Not accepted",R15,IF(OR(X15="Accepted",X15="Withdrawn by hospital"),IF(X15="Accepted",0,R15),IF(ISNUMBER(Z15),R15-Z15,"")))) | AI15: =IF(X15="Not accepted","Maintained",IF(X15="Partially accepted","Partially maintained",IF(X15="Accepted","Reversed",IF(X15="Withdrawn by hospital","Withdrawn by hospital","")))) | AJ15: =IF(AI15="","",W15) | AK15: =IF(AND(ISNUMBER(T15),ISNUMBER(W15)),W15-T15,"") | AL15: =IF(A15="","",SUMIF(Actions!$C$5:$C$1004,A15,Actions!$F$5:$F$1004))
R16: =IF(AND(ISNUMBER(P16),ISNUMBER(Q16)),P16-Q16,"") | T16: =IF(S16<>"",S16,IF(B16="","",IFERROR(IF(INDEX(Batches!$G$5:$G$64,MATCH(B16,Batches!$A$5:$A$64,0))="","",INDEX(Batches!$G$5:$G$64,MATCH(B16,Batches!$A$5:$A$64,0))),""))) | W16: =IF(OR(X16="",X16="Pending"),"",IF(V16<>"",V16,IFERROR(IF(INDEX(Batches!$H$5:$H$64,MATCH(B16,Batches!$A$5:$A$64,0))="","",INDEX(Batches!$H$5:$H$64,MATCH(B16,Batches!$A$5:$A$64,0))),""))) | AA16: =IF(R16="","",IF(X16="Not accepted",R16,IF(OR(X16="Accepted",X16="Withdrawn by hospital"),IF(X16="Accepted",0,R16),IF(ISNUMBER(Z16),R16-Z16,"")))) | AI16: =IF(X16="Not accepted","Maintained",IF(X16="Partially accepted","Partially maintained",IF(X16="Accepted","Reversed",IF(X16="Withdrawn by hospital","Withdrawn by hospital","")))) | AJ16: =IF(AI16="","",W16) | AK16: =IF(AND(ISNUMBER(T16),ISNUMBER(W16)),W16-T16,"") | AL16: =IF(A16="","",SUMIF(Actions!$C$5:$C$1004,A16,Actions!$F$5:$F$1004))
... R1004: =IF(AND(ISNUMBER(P1004),ISNUMBER(Q1004)),P1004-Q1004,"") | T1004: =IF(S1004<>"",S1004,IF(B1004="","",IFERROR(IF(INDEX(Batches!$G$5:$G$64,MATCH(B1004,Batches!$A$5:$A$64,0))="","",INDEX(Batches!$G$5:$G$64,MATCH(B1004,Batches!$A$5:$A$64,0))),""))) | W1004: =IF(OR(X1004="",X1004="Pending"),"",IF(V1004<>"",V1004,IFERROR(IF(INDEX(Batches!$H$5:$H$64,MATCH(B1004,Batches!$A$5:$A$64,0))="","",INDEX(Batches!$H$5:$H$64,MATCH(B1004,Batches!$A$5:$A$64,0))),""))) | AA1004: =IF(R1004="","",IF(X1004="Not accepted",R1004,IF(OR(X1004="Accepted",X1004="Withdrawn by hospital"),IF(X1004="Accepted",0,R1004),IF(ISNUMBER(Z1004),R1004-Z1004,"")))) | AI1004: =IF(X1004="Not accepted","Maintained",IF(X1004="Partially accepted","Partially maintained",IF(X1004="Accepted","Reversed",IF(X1004="Withdrawn by hospital","Withdrawn by hospital","")))) | AJ1004: =IF(AI1004="","",W1004) | AK1004: =IF(AND(ISNUMBER(T1004),ISNUMBER(W1004)),W1004-T1004,"") | AL1004: =IF(A1004="","",SUMIF(Actions!$C$5:$C$1004,A1004,Actions!$F$5:$F$1004))

Sheet Actions
A1: Actions and time log: one row per action taken on a dispute or batch
A2: Log every action with its hours from 1 October 2026. Use a Batch ID or 'General' when the work covers several disputes. Row 5 is an example.
A4: Action ID | B4: Date | C4: Dispute ID | D4: Action type | E4: Team member | F4: Hours | G4: Estimated? (backfilled) | H4: Note | I4: Hospital | J4: Month
A5: A-EXAMPLE | B5: 46322 | C5: EXAMPLE | D5: Clinical review | E5: Reviewer 1 | F5: 1.5 | G5: No | H5: Example row: replace with your first action | I5: =IF(C5="","",IFERROR(INDEX(Disputes!$C$5:$C$1004,MATCH(C5,Disputes!$A$5:$A$1004,0)),IFERROR(INDEX(Batches!$B$5:$B$64,MATCH(C5,Batches!$A$5:$A$64,0)),""))) | J5: =IF(B5="","",DATE(YEAR(B5),MONTH(B5),1)) -> 46296
I6: =IF(C6="","",IFERROR(INDEX(Disputes!$C$5:$C$1004,MATCH(C6,Disputes!$A$5:$A$1004,0)),IFERROR(INDEX(Batches!$B$5:$B$64,MATCH(C6,Batches!$A$5:$A$64,0)),""))) | J6: =IF(B6="","",DATE(YEAR(B6),MONTH(B6),1))
I7: =IF(C7="","",IFERROR(INDEX(Disputes!$C$5:$C$1004,MATCH(C7,Disputes!$A$5:$A$1004,0)),IFERROR(INDEX(Batches!$B$5:$B$64,MATCH(C7,Batches!$A$5:$A$64,0)),""))) | J7: =IF(B7="","",DATE(YEAR(B7),MONTH(B7),1))
I8: =IF(C8="","",IFERROR(INDEX(Disputes!$C$5:$C$1004,MATCH(C8,Disputes!$A$5:$A$1004,0)),IFERROR(INDEX(Batches!$B$5:$B$64,MATCH(C8,Batches!$A$5:$A$64,0)),""))) | J8: =IF(B8="","",DATE(YEAR(B8),MONTH(B8),1))
I9: =IF(C9="","",IFERROR(INDEX(Disputes!$C$5:$C$1004,MATCH(C9,Disputes!$A$5:$A$1004,0)),IFERROR(INDEX(Batches!$B$5:$B$64,MATCH(C9,Batches!$A$5:$A$64,0)),""))) | J9: =IF(B9="","",DATE(YEAR(B9),MONTH(B9),1))
I10: =IF(C10="","",IFERROR(INDEX(Disputes!$C$5:$C$1004,MATCH(C10,Disputes!$A$5:$A$1004,0)),IFERROR(INDEX(Batches!$B$5:$B$64,MATCH(C10,Batches!$A$5:$A$64,0)),""))) | J10: =IF(B10="","",DATE(YEAR(B10),MONTH(B10),1))
I11: =IF(C11="","",IFERROR(INDEX(Disputes!$C$5:$C$1004,MATCH(C11,Disputes!$A$5:$A$1004,0)),IFERROR(INDEX(Batches!$B$5:$B$64,MATCH(C11,Batches!$A$5:$A$64,0)),""))) | J11: =IF(B11="","",DATE(YEAR(B11),MONTH(B11),1))
I12: =IF(C12="","",IFERROR(INDEX(Disputes!$C$5:$C$1004,MATCH(C12,Disputes!$A$5:$A$1004,0)),IFERROR(INDEX(Batches!$B$5:$B$64,MATCH(C12,Batches!$A$5:$A$64,0)),""))) | J12: =IF(B12="","",DATE(YEAR(B12),MONTH(B12),1))
I13: =IF(C13="","",IFERROR(INDEX(Disputes!$C$5:$C$1004,MATCH(C13,Disputes!$A$5:$A$1004,0)),IFERROR(INDEX(Batches!$B$5:$B$64,MATCH(C13,Batches!$A$5:$A$64,0)),""))) | J13: =IF(B13="","",DATE(YEAR(B13),MONTH(B13),1))
I14: =IF(C14="","",IFERROR(INDEX(Disputes!$C$5:$C$1004,MATCH(C14,Disputes!$A$5:$A$1004,0)),IFERROR(INDEX(Batches!$B$5:$B$64,MATCH(C14,Batches!$A$5:$A$64,0)),""))) | J14: =IF(B14="","",DATE(YEAR(B14),MONTH(B14),1))
I15: =IF(C15="","",IFERROR(INDEX(Disputes!$C$5:$C$1004,MATCH(C15,Disputes!$A$5:$A$1004,0)),IFERROR(INDEX(Batches!$B$5:$B$64,MATCH(C15,Batches!$A$5:$A$64,0)),""))) | J15: =IF(B15="","",DATE(YEAR(B15),MONTH(B15),1))
I16: =IF(C16="","",IFERROR(INDEX(Disputes!$C$5:$C$1004,MATCH(C16,Disputes!$A$5:$A$1004,0)),IFERROR(INDEX(Batches!$B$5:$B$64,MATCH(C16,Batches!$A$5:$A$64,0)),""))) | J16: =IF(B16="","",DATE(YEAR(B16),MONTH(B16),1))
I17: =IF(C17="","",IFERROR(INDEX(Disputes!$C$5:$C$1004,MATCH(C17,Disputes!$A$5:$A$1004,0)),IFERROR(INDEX(Batches!$B$5:$B$64,MATCH(C17,Batches!$A$5:$A$64,0)),""))) | J17: =IF(B17="","",DATE(YEAR(B17),MONTH(B17),1))
... I1004: =IF(C1004="","",IFERROR(INDEX(Disputes!$C$5:$C$1004,MATCH(C1004,Disputes!$A$5:$A$1004,0)),IFERROR(INDEX(Batches!$B$5:$B$64,MATCH(C1004,Batches!$A$5:$A$64,0)),""))) | J1004: =IF(B1004="","",DATE(YEAR(B1004),MONTH(B1004),1))

Sheet Rejection codes
A1: NPHIES rejection codes seen in the disputes
A2: Descriptions as they appear in the claim responses. Add new codes as they appear.
A4: Code | B4: Description | C4: Code group | D4: Disputes citing it
A5: AD-3-3 | B5: Room services and food are included in room and board expenses | C5: Administrative | D5: =COUNTIF(Disputes!$L$5:$L$1004,"*"&A5&"*") -> 0
A6: BE-1-2 | B6: Service was not performed | C6: Billing and authorization | D6: =COUNTIF(Disputes!$L$5:$L$1004,"*"&A6&"*") -> 0
A7: BE-1-3 | B7: Submission not compliant with contractual agreement between provider & payer | C7: Billing and authorization | D7: =COUNTIF(Disputes!$L$5:$L$1004,"*"&A7&"*") -> 0
A8: BE-1-4 | B8: Preauthorization is required and was not obtained | C8: Billing and authorization | D8: =COUNTIF(Disputes!$L$5:$L$1004,"*"&A8&"*") -> 0
A9: BE-1-6 | B9: Calculation discrepancy | C9: Billing and authorization | D9: =COUNTIF(Disputes!$L$5:$L$1004,"*"&A9&"*") -> 0
A10: BE-1-7 | B10: Incorrect billing regime | C10: Billing and authorization | D10: =COUNTIF(Disputes!$L$5:$L$1004,"*"&A10&"*") -> 0
A11: CV-4-9 | B11: Service/procedure/device/medication was included within another service/procedure | C11: Coding and bundling | D11: =COUNTIF(Disputes!$L$5:$L$1004,"*"&A11&"*") -> 0
A12: MN-1-1 | B12: Service is not clinically justified based on clinical practice guideline, without additional supporting diagnosis | C12: Medical necessity | D12: =COUNTIF(Disputes!$L$5:$L$1004,"*"&A12&"*") -> 0
A13: SE-1-7 | B13: Type of diagnosis is inadequate or missing | C13: Supporting documentation | D13: =COUNTIF(Disputes!$L$5:$L$1004,"*"&A13&"*") -> 0
A14: SE-1-8 | B14: Treatment plan is inadequate or missing | C14: Supporting documentation | D14: =COUNTIF(Disputes!$L$5:$L$1004,"*"&A14&"*") -> 0

Sheet Lists
A1: Lists
A2: Add items at the bottom of a list with no gaps; drop-downs read these lists.
A4: Hospital | B4: TPA | C4: Pathway | D4: Round | E4: Theme | F4: KPMG position | G4: Action | H4: FWA | I4: Status | J4: CNHI decision | K4: Action type | L4: Yes/No
A5: Al-Ahly Hospital | B5: GlobeMed Saudi | C5: Claim | D5: 1st objection | E5: Level of care (ICU/PICU) | F5: Not accepted | G5: Uphold rejection | H5: None | I5: Received | J5: Agreed with KPMG | K5: Batch received | L5: No
A6: Al Khafji Ahli Hospital | B6: NextCare | C6: Pre-authorization | D6: 2nd objection | E6: Length of stay | F6: Partially accepted | G6: Partial payment | H6: Waste (overpayment risk) | I6: Pending KPMG review | J6: Partially agreed | K6: Case triage | L6: Yes
A7: Dr. Fares Al-Haddaj Hospital | B7: CNHI (direct) | C7: GSS | D7: 3rd objection | E7: Pre-authorization missing or expired | F7: Accepted | G7: Overturn - pay in full | H7: Potential abuse | I7: Documents requested | J7: Disagreed | K7: Clinical review
A8: Almodawat Hospital | B8: Other | E8: Coding or billing | F8: Withdrawn by hospital | G8: Reprice (correct code or tariff) | H8: Suspected abuse | I8: KPMG opinion issued | J8: Pending | K8: Documents requested
E9: Long-term care / ventilation | F9: Pending | G9: Reprocess with correct code | H9: Suspected fraud | I9: Sent to CNHI | K9: Response drafted
E10: Medical necessity | G10: Request documents | I10: Closed - CNHI decision recorded | K10: Internal QA
E11: Pricing or tariff | G11: Refer for FWA investigation | K11: Opinion issued to CNHI
E12: Documentation | K12: Meeting with hospital, TPA or CNHI
E13: Other | K13: CNHI decision recorded
K14: Other
